2025-01-13 18:26:03,568 INFO    MainThread:492 [wandb_setup.py:_flush():68] Current SDK version is 0.19.2
2025-01-13 18:26:03,569 INFO    MainThread:492 [wandb_setup.py:_flush():68] Configure stats pid to 492
2025-01-13 18:26:03,569 INFO    MainThread:492 [wandb_setup.py:_flush():68] Loading settings from C:\Users\DeLL\.config\wandb\settings
2025-01-13 18:26:03,569 INFO    MainThread:492 [wandb_setup.py:_flush():68] Loading settings from C:\Users\DeLL\Documents\masterIA S1\Intro IA\min_porject\wandb\settings
2025-01-13 18:26:03,569 INFO    MainThread:492 [wandb_setup.py:_flush():68] Loading settings from environment variables
2025-01-13 18:26:03,570 INFO    MainThread:492 [wandb_init.py:_log_setup():523] Logging user logs to C:\Users\DeLL\Documents\masterIA S1\Intro IA\min_porject\wandb\run-20250113_182603-5a5fwp94\logs\debug.log
2025-01-13 18:26:03,570 INFO    MainThread:492 [wandb_init.py:_log_setup():524] Logging internal logs to C:\Users\DeLL\Documents\masterIA S1\Intro IA\min_porject\wandb\run-20250113_182603-5a5fwp94\logs\debug-internal.log
2025-01-13 18:26:03,570 INFO    MainThread:492 [wandb_init.py:init():641] calling init triggers
2025-01-13 18:26:03,571 INFO    MainThread:492 [wandb_init.py:init():647] wandb.init called with sweep_config: {}
config: {}
2025-01-13 18:26:03,571 INFO    MainThread:492 [wandb_init.py:init():674] starting backend
2025-01-13 18:26:04,502 INFO    MainThread:492 [wandb_init.py:init():678] sending inform_init request
2025-01-13 18:26:04,569 INFO    MainThread:492 [backend.py:_multiprocessing_setup():104] multiprocessing start_methods=spawn, using: spawn
2025-01-13 18:26:04,569 INFO    MainThread:492 [wandb_init.py:init():693] backend started and connected
2025-01-13 18:26:04,571 INFO    MainThread:492 [wandb_init.py:init():786] updated telemetry
2025-01-13 18:26:04,727 INFO    MainThread:492 [wandb_init.py:init():818] communicating run to backend with 90.0 second timeout
2025-01-13 18:26:05,403 ERROR   MainThread:492 [wandb_init.py:init():845] encountered error: failed to upsert bucket: returned error 404 Not Found: {"errors":[{"message":"entity votre-nom-utilisateur not found during upsertBucket","path":["upsertBucket"]}],"data":{"upsertBucket":null}}
2025-01-13 18:26:05,404 ERROR   MainThread:492 [wandb_init.py:init():1299] error in wandb.init()
Traceback (most recent call last):
  File "C:\Users\DeLL\Documents\masterIA S1\Intro IA\min_porject\myenv\Lib\site-packages\wandb\sdk\wandb_init.py", line 1289, in init
    return wi.init()
           ^^^^^^^^^
  File "C:\Users\DeLL\Documents\masterIA S1\Intro IA\min_porject\myenv\Lib\site-packages\wandb\sdk\wandb_init.py", line 851, in init
    raise error
wandb.errors.errors.CommError: failed to upsert bucket: returned error 404 Not Found: {"errors":[{"message":"entity votre-nom-utilisateur not found during upsertBucket","path":["upsertBucket"]}],"data":{"upsertBucket":null}}
2025-01-13 18:26:05,465 WARNING MsgRouterThr:492 [router.py:message_loop():75] message_loop has been closed
