Traceback (most recent call last):
  File "C:\Users\DeLL\Documents\masterIA S1\Intro IA\min_porject\myenv\Lib\site-packages\pandas\core\indexes\base.py", line 3805, in get_loc
    return self._engine.get_loc(casted_key)
           ^^^^^^^^^^^^^^^^^^^^^^^^^^^^^^^^
  File "index.pyx", line 167, in pandas._libs.index.IndexEngine.get_loc
  File "index.pyx", line 196, in pandas._libs.index.IndexEngine.get_loc
  File "pandas\\_libs\\hashtable_class_helper.pxi", line 7081, in pandas._libs.hashtable.PyObjectHashTable.get_item
  File "pandas\\_libs\\hashtable_class_helper.pxi", line 7089, in pandas._libs.hashtable.PyObjectHashTable.get_item
KeyError: 'tweet'

The above exception was the direct cause of the following exception:

Traceback (most recent call last):
  File "C:\Users\DeLL\Documents\masterIA S1\Intro IA\min_porject\script\train-and-evaluation-model.py", line 88, in <module>
    train_and_log_model(dataset_path, model_path)
  File "C:\Users\DeLL\Documents\masterIA S1\Intro IA\min_porject\script\train-and-evaluation-model.py", line 35, in train_and_log_model
    X, y = load_data(dataset_path)
           ^^^^^^^^^^^^^^^^^^^^^^^
  File "C:\Users\DeLL\Documents\masterIA S1\Intro IA\min_porject\script\train-and-evaluation-model.py", line 19, in load_data
    X = data['tweet']  # Colonne contenant les textes
        ~~~~^^^^^^^^^
  File "C:\Users\DeLL\Documents\masterIA S1\Intro IA\min_porject\myenv\Lib\site-packages\pandas\core\frame.py", line 4102, in __getitem__
    indexer = self.columns.get_loc(key)
              ^^^^^^^^^^^^^^^^^^^^^^^^^
  File "C:\Users\DeLL\Documents\masterIA S1\Intro IA\min_porject\myenv\Lib\site-packages\pandas\core\indexes\base.py", line 3812, in get_loc
    raise KeyError(key) from err
KeyError: 'tweet'
